Workbook

Sheet README
A1: Caboodle — Jira Backlog Organized by Module
A3: Purpose | B3: 225 open tickets (Backlog / In Progress / In Staging / Ready for Production / Reopened) classified into the Caboodle module hierarchy to plan the 3-month sprint ahead of new-client onboarding.
A4: How it was built | B4: Each ticket was assigned an Area + Caboodle Module by reading its Summary (which references the module), with the original Jira "Module" column used as backup. The [FE]/[BE] tag was parsed from the summary into the FE/BE column for engineer allocation.
A6: TABS
A7: Module Summary | B7: Live count of tickets per module, broken out by status, priority, and FE vs BE. Formula-driven — edits to the Master tab flow through automatically.
A8: All Tickets (Master) | B8: Every ticket with its assigned Area, Module and FE/BE tag. This is the source of truth; the area tabs and summary read from it.
A9: Broker Dashboard / Brand / Reports / Admin / Platform | B9: One tab per Area, tickets grouped under their module heading and sorted by priority.
A11: NOTES & JUDGMENT CALLS
A12: Category Review | B12: Appears in two places: under Broker Dashboard (the broker-side review tool) and under Reports as "Category Review Report". Tickets tagged "Reports | Category Review" went to the report; the rest to Broker Dashboard.
A13: Trade Spend | B13: "Trade Spend Sandbox / TSS / EDLP / Everyday Allowance" → Brand module Trade Spend Sandbox. "Trade Spend Roll Up / Rollup Report" → Reports module Trade Spend Rollup.
A14: Platform & Cross-Cutting | B14: 30 tickets that do not belong to any single module — DB indexing, code refactor, caching, email service, QA/UX audits, big-data upload wizard, Ask Caboodle (AI), Tableau, margin calculator. Worth scoping separately from module work.
A15: Two new reports | B15: "Banner-to-DC Reporting" is flagged as a new report (not in the current 8-report list).
A16: Re-binning | B16: Because the Area & Module columns live on every row, you can re-sort or re-classify any ticket and the Module Summary updates instantly.

Sheet Module Summary
A1: Tickets by Caboodle Module
A3: Area | B3: Caboodle Module | C3: Total | D3: Backlog | E3: In Progress | F3: In Staging | G3: Ready for Prod | H3: Reopened | I3: Highest | J3: High | K3: Medium | L3: Low | M3: FE | N3: BE
A4: Broker Dashboard | B4: Market Overview | C4: =COUNTIFS('All Tickets (Master)'!$D$2:$D$227,$A4,'All Tickets (Master)'!$E$2:$E$227,$B4) -> 6 | D4: =COUNTIFS('All Tickets (Master)'!$D$2:$D$227,$A4,'All Tickets (Master)'!$E$2:$E$227,$B4,'All Tickets (Master)'!$H$2:$H$227,"Backlog") -> 5 | E4: =COUNTIFS('All Tickets (Master)'!$D$2:$D$227,$A4,'All Tickets (Master)'!$E$2:$E$227,$B4,'All Tickets (Master)'!$H$2:$H$227,"In Progress") -> 1 | F4: =COUNTIFS('All Tickets (Master)'!$D$2:$D$227,$A4,'All Tickets (Master)'!$E$2:$E$227,$B4,'All Tickets (Master)'!$H$2:$H$227,"In Staging") -> 0 | G4: =COUNTIFS('All Tickets (Master)'!$D$2:$D$227,$A4,'All Tickets (Master)'!$E$2:$E$227,$B4,'All Tickets (Master)'!$H$2:$H$227,"Ready for Production") -> 0 | H4: =COUNTIFS('All Tickets (Master)'!$D$2:$D$227,$A4,'All Tickets (Master)'!$E$2:$E$227,$B4,'All Tickets (Master)'!$H$2:$H$227,"Reopened") -> 0 | I4: =COUNTIFS('All Tickets (Master)'!$D$2:$D$227,$A4,'All Tickets (Master)'!$E$2:$E$227,$B4,'All Tickets (Master)'!$G$2:$G$227,"Highest") -> 0 | J4: =COUNTIFS('All Tickets (Master)'!$D$2:$D$227,$A4,'All Tickets (Master)'!$E$2:$E$227,$B4,'All Tickets (Master)'!$G$2:$G$227,"High") -> 6 | K4: =COUNTIFS('All Tickets (Master)'!$D$2:$D$227,$A4,'All Tickets (Master)'!$E$2:$E$227,$B4,'All Tickets (Master)'!$G$2:$G$227,"Medium") -> 0 | L4: =COUNTIFS('All Tickets (Master)'!$D$2:$D$227,$A4,'All Tickets (Master)'!$E$2:$E$227,$B4,'All Tickets (Master)'!$G$2:$G$227,"Low") -> 0 | M4: =COUNTIFS('All Tickets (Master)'!$D$2:$D$227,$A4,'All Tickets (Master)'!$E$2:$E$227,$B4,'All Tickets (Master)'!$F$2:$F$227,"FE") -> 0 | N4: =COUNTIFS('All Tickets (Master)'!$D$2:$D$227,$A4,'All Tickets (Master)'!$E$2:$E$227,$B4,'All Tickets (Master)'!$F$2:$F$227,"BE") -> 1
A5: Broker Dashboard | B5: Promotional Management | C5: =COUNTIFS('All Tickets (Master)'!$D$2:$D$227,$A5,'All Tickets (Master)'!$E$2:$E$227,$B5) -> 5 | D5: =COUNTIFS('All Tickets (Master)'!$D$2:$D$227,$A5,'All Tickets (Master)'!$E$2:$E$227,$B5,'All Tickets (Master)'!$H$2:$H$227,"Backlog") -> 5 | E5: =COUNTIFS('All Tickets (Master)'!$D$2:$D$227,$A5,'All Tickets (Master)'!$E$2:$E$227,$B5,'All Tickets (Master)'!$H$2:$H$227,"In Progress") -> 0 | F5: =COUNTIFS('All Tickets (Master)'!$D$2:$D$227,$A5,'All Tickets (Master)'!$E$2:$E$227,$B5,'All Tickets (Master)'!$H$2:$H$227,"In Staging") -> 0 | G5: =COUNTIFS('All Tickets (Master)'!$D$2:$D$227,$A5,'All Tickets (Master)'!$E$2:$E$227,$B5,'All Tickets (Master)'!$H$2:$H$227,"Ready for Production") -> 0 | H5: =COUNTIFS('All Tickets (Master)'!$D$2:$D$227,$A5,'All Tickets (Master)'!$E$2:$E$227,$B5,'All Tickets (Master)'!$H$2:$H$227,"Reopened") -> 0 | I5: =COUNTIFS('All Tickets (Master)'!$D$2:$D$227,$A5,'All Tickets (Master)'!$E$2:$E$227,$B5,'All Tickets (Master)'!$G$2:$G$227,"Highest") -> 0 | J5: =COUNTIFS('All Tickets (Master)'!$D$2:$D$227,$A5,'All Tickets (Master)'!$E$2:$E$227,$B5,'All Tickets (Master)'!$G$2:$G$227,"High") -> 3 | K5: =COUNTIFS('All Tickets (Master)'!$D$2:$D$227,$A5,'All Tickets (Master)'!$E$2:$E$227,$B5,'All Tickets (Master)'!$G$2:$G$227,"Medium") -> 1 | L5: =COUNTIFS('All Tickets (Master)'!$D$2:$D$227,$A5,'All Tickets (Master)'!$E$2:$E$227,$B5,'All Tickets (Master)'!$G$2:$G$227,"Low") -> 1 | M5: =COUNTIFS('All Tickets (Master)'!$D$2:$D$227,$A5,'All Tickets (Master)'!$E$2:$E$227,$B5,'All Tickets (Master)'!$F$2:$F$227,"FE") -> 0 | N5: =COUNTIFS('All Tickets (Master)'!$D$2:$D$227,$A5,'All Tickets (Master)'!$E$2:$E$227,$B5,'All Tickets (Master)'!$F$2:$F$227,"BE") -> 2
A6: Broker Dashboard | B6: Category Review | C6: =COUNTIFS('All Tickets (Master)'!$D$2:$D$227,$A6,'All Tickets (Master)'!$E$2:$E$227,$B6) -> 11 | D6: =COUNTIFS('All Tickets (Master)'!$D$2:$D$227,$A6,'All Tickets (Master)'!$E$2:$E$227,$B6,'All Tickets (Master)'!$H$2:$H$227,"Backlog") -> 9 | E6: =COUNTIFS('All Tickets (Master)'!$D$2:$D$227,$A6,'All Tickets (Master)'!$E$2:$E$227,$B6,'All Tickets (Master)'!$H$2:$H$227,"In Progress") -> 1 | F6: =COUNTIFS('All Tickets (Master)'!$D$2:$D$227,$A6,'All Tickets (Master)'!$E$2:$E$227,$B6,'All Tickets (Master)'!$H$2:$H$227,"In Staging") -> 0 | G6: =COUNTIFS('All Tickets (Master)'!$D$2:$D$227,$A6,'All Tickets (Master)'!$E$2:$E$227,$B6,'All Tickets (Master)'!$H$2:$H$227,"Ready for Production") -> 0 | H6: =COUNTIFS('All Tickets (Master)'!$D$2:$D$227,$A6,'All Tickets (Master)'!$E$2:$E$227,$B6,'All Tickets (Master)'!$H$2:$H$227,"Reopened") -> 1 | I6: =COUNTIFS('All Tickets (Master)'!$D$2:$D$227,$A6,'All Tickets (Master)'!$E$2:$E$227,$B6,'All Tickets (Master)'!$G$2:$G$227,"Highest") -> 1 | J6: =COUNTIFS('All Tickets (Master)'!$D$2:$D$227,$A6,'All Tickets (Master)'!$E$2:$E$227,$B6,'All Tickets (Master)'!$G$2:$G$227,"High") -> 10 | K6: =COUNTIFS('All Tickets (Master)'!$D$2:$D$227,$A6,'All Tickets (Master)'!$E$2:$E$227,$B6,'All Tickets (Master)'!$G$2:$G$227,"Medium") -> 0 | L6: =COUNTIFS('All Tickets (Master)'!$D$2:$D$227,$A6,'All Tickets (Master)'!$E$2:$E$227,$B6,'All Tickets (Master)'!$G$2:$G$227,"Low") -> 0 | M6: =COUNTIFS('All Tickets (Master)'!$D$2:$D$227,$A6,'All Tickets (Master)'!$E$2:$E$227,$B6,'All Tickets (Master)'!$F$2:$F$227,"FE") -> 0 | N6: =COUNTIFS('All Tickets (Master)'!$D$2:$D$227,$A6,'All Tickets (Master)'!$E$2:$E$227,$B6,'All Tickets (Master)'!$F$2:$F$227,"BE") -> 0
A7: Broker Dashboard | B7: Distributor APL | C7: =COUNTIFS('All Tickets (Master)'!$D$2:$D$227,$A7,'All Tickets (Master)'!$E$2:$E$227,$B7) -> 4 | D7: =COUNTIFS('All Tickets (Master)'!$D$2:$D$227,$A7,'All Tickets (Master)'!$E$2:$E$227,$B7,'All Tickets (Master)'!$H$2:$H$227,"Backlog") -> 4 | E7: =COUNTIFS('All Tickets (Master)'!$D$2:$D$227,$A7,'All Tickets (Master)'!$E$2:$E$227,$B7,'All Tickets (Master)'!$H$2:$H$227,"In Progress") -> 0 | F7: =COUNTIFS('All Tickets (Master)'!$D$2:$D$227,$A7,'All Tickets (Master)'!$E$2:$E$227,$B7,'All Tickets (Master)'!$H$2:$H$227,"In Staging") -> 0 | G7: =COUNTIFS('All Tickets (Master)'!$D$2:$D$227,$A7,'All Tickets (Master)'!$E$2:$E$227,$B7,'All Tickets (Master)'!$H$2:$H$227,"Ready for Production") -> 0 | H7: =COUNTIFS('All Tickets (Master)'!$D$2:$D$227,$A7,'All Tickets (Master)'!$E$2:$E$227,$B7,'All Tickets (Master)'!$H$2:$H$227,"Reopened") -> 0 | I7: =COUNTIFS('All Tickets (Master)'!$D$2:$D$227,$A7,'All Tickets (Master)'!$E$2:$E$227,$B7,'All Tickets (Master)'!$G$2:$G$227,"Highest") -> 1 | J7: =COUNTIFS('All Tickets (Master)'!$D$2:$D$227,$A7,'All Tickets (Master)'!$E$2:$E$227,$B7,'All Tickets (Master)'!$G$2:$G$227,"High") -> 3 | K7: =COUNTIFS('All Tickets (Master)'!$D$2:$D$227,$A7,'All Tickets (Master)'!$E$2:$E$227,$B7,'All Tickets (Master)'!$G$2:$G$227,"Medium") -> 0 | L7: =COUNTIFS('All Tickets (Master)'!$D$2:$D$227,$A7,'All Tickets (Master)'!$E$2:$E$227,$B7,'All Tickets (Master)'!$G$2:$G$227,"Low") -> 0 | M7: =COUNTIFS('All Tickets (Master)'!$D$2:$D$227,$A7,'All Tickets (Master)'!$E$2:$E$227,$B7,'All Tickets (Master)'!$F$2:$F$227,"FE") -> 0 | N7: =COUNTIFS('All Tickets (Master)'!$D$2:$D$227,$A7,'All Tickets (Master)'!$E$2:$E$227,$B7,'All Tickets (Master)'!$F$2:$F$227,"BE") -> 0
A8: Broker Dashboard | B8: Files | C8: =COUNTIFS('All Tickets (Master)'!$D$2:$D$227,$A8,'All Tickets (Master)'!$E$2:$E$227,$B8) -> 3 | D8: =COUNTIFS('All Tickets (Master)'!$D$2:$D$227,$A8,'All Tickets (Master)'!$E$2:$E$227,$B8,'All Tickets (Master)'!$H$2:$H$227,"Backlog") -> 3 | E8: =COUNTIFS('All Tickets (Master)'!$D$2:$D$227,$A8,'All Tickets (Master)'!$E$2:$E$227,$B8,'All Tickets (Master)'!$H$2:$H$227,"In Progress") -> 0 | F8: =COUNTIFS('All Tickets (Master)'!$D$2:$D$227,$A8,'All Tickets (Master)'!$E$2:$E$227,$B8,'All Tickets (Master)'!$H$2:$H$227,"In Staging") -> 0 | G8: =COUNTIFS('All Tickets (Master)'!$D$2:$D$227,$A8,'All Tickets (Master)'!$E$2:$E$227,$B8,'All Tickets (Master)'!$H$2:$H$227,"Ready for Production") -> 0 | H8: =COUNTIFS('All Tickets (Master)'!$D$2:$D$227,$A8,'All Tickets (Master)'!$E$2:$E$227,$B8,'All Tickets (Master)'!$H$2:$H$227,"Reopened") -> 0 | I8: =COUNTIFS('All Tickets (Master)'!$D$2:$D$227,$A8,'All Tickets (Master)'!$E$2:$E$227,$B8,'All Tickets (Master)'!$G$2:$G$227,"Highest") -> 2 | J8: =COUNTIFS('All Tickets (Master)'!$D$2:$D$227,$A8,'All Tickets (Master)'!$E$2:$E$227,$B8,'All Tickets (Master)'!$G$2:$G$227,"High") -> 1 | K8: =COUNTIFS('All Tickets (Master)'!$D$2:$D$227,$A8,'All Tickets (Master)'!$E$2:$E$227,$B8,'All Tickets (Master)'!$G$2:$G$227,"Medium") -> 0 | L8: =COUNTIFS('All Tickets (Master)'!$D$2:$D$227,$A8,'All Tickets (Master)'!$E$2:$E$227,$B8,'All Tickets (Master)'!$G$2:$G$227,"Low") -> 0 | M8: =COUNTIFS('All Tickets (Master)'!$D$2:$D$227,$A8,'All Tickets (Master)'!$E$2:$E$227,$B8,'All Tickets (Master)'!$F$2:$F$227,"FE") -> 0 | N8: =COUNTIFS('All Tickets (Master)'!$D$2:$D$227,$A8,'All Tickets (Master)'!$E$2:$E$227,$B8,'All Tickets (Master)'!$F$2:$F$227,"BE") -> 0
A9: Broker Dashboard | B9: Broker Dashboard (General) | C9: =COUNTIFS('All Tickets (Master)'!$D$2:$D$227,$A9,'All Tickets (Master)'!$E$2:$E$227,$B9) -> 4 | D9: =COUNTIFS('All Tickets (Master)'!$D$2:$D$227,$A9,'All Tickets (Master)'!$E$2:$E$227,$B9,'All Tickets (Master)'!$H$2:$H$227,"Backlog") -> 4 | E9: =COUNTIFS('All Tickets (Master)'!$D$2:$D$227,$A9,'All Tickets (Master)'!$E$2:$E$227,$B9,'All Tickets (Master)'!$H$2:$H$227,"In Progress") -> 0 | F9: =COUNTIFS('All Tickets (Master)'!$D$2:$D$227,$A9,'All Tickets (Master)'!$E$2:$E$227,$B9,'All Tickets (Master)'!$H$2:$H$227,"In Staging") -> 0 | G9: =COUNTIFS('All Tickets (Master)'!$D$2:$D$227,$A9,'All Tickets (Master)'!$E$2:$E$227,$B9,'All Tickets (Master)'!$H$2:$H$227,"Ready for Production") -> 0 | H9: =COUNTIFS('All Tickets (Master)'!$D$2:$D$227,$A9,'All Tickets (Master)'!$E$2:$E$227,$B9,'All Tickets (Master)'!$H$2:$H$227,"Reopened") -> 0 | I9: =COUNTIFS('All Tickets (Master)'!$D$2:$D$227,$A9,'All Tickets (Master)'!$E$2:$E$227,$B9,'All Tickets (Master)'!$G$2:$G$227,"Highest") -> 0 | J9: =COUNTIFS('All Tickets (Master)'!$D$2:$D$227,$A9,'All Tickets (Master)'!$E$2:$E$227,$B9,'All Tickets (Master)'!$G$2:$G$227,"High") -> 3 | K9: =COUNTIFS('All Tickets (Master)'!$D$2:$D$227,$A9,'All Tickets (Master)'!$E$2:$E$227,$B9,'All Tickets (Master)'!$G$2:$G$227,"Medium") -> 0 | L9: =COUNTIFS('All Tickets (Master)'!$D$2:$D$227,$A9,'All Tickets (Master)'!$E$2:$E$227,$B9,'All Tickets (Master)'!$G$2:$G$227,"Low") -> 1 | M9: =COUNTIFS('All Tickets (Master)'!$D$2:$D$227,$A9,'All Tickets (Master)'!$E$2:$E$227,$B9,'All Tickets (Master)'!$F$2:$F$227,"FE") -> 0 | N9: =COUNTIFS('All Tickets (Master)'!$D$2:$D$227,$A9,'All Tickets (Master)'!$E$2:$E$227,$B9,'All Tickets (Master)'!$F$2:$F$227,"BE") -> 1
A10: Brand | B10: Product Specs | C10: =COUNTIFS('All Tickets (Master)'!$D$2:$D$227,$A10,'All Tickets (Master)'!$E$2:$E$227,$B10) -> 8 | D10: =COUNTIFS('All Tickets (Master)'!$D$2:$D$227,$A10,'All Tickets (Master)'!$E$2:$E$227,$B10,'All Tickets (Master)'!$H$2:$H$227,"Backlog") -> 5 | E10: =COUNTIFS('All Tickets (Master)'!$D$2:$D$227,$A10,'All Tickets (Master)'!$E$2:$E$227,$B10,'All Tickets (Master)'!$H$2:$H$227,"In Progress") -> 1 | F10: =COUNTIFS('All Tickets (Master)'!$D$2:$D$227,$A10,'All Tickets (Master)'!$E$2:$E$227,$B10,'All Tickets (Master)'!$H$2:$H$227,"In Staging") -> 0 | G10: =COUNTIFS('All Tickets (Master)'!$D$2:$D$227,$A10,'All Tickets (Master)'!$E$2:$E$227,$B10,'All Tickets (Master)'!$H$2:$H$227,"Ready for Production") -> 0 | H10: =COUNTIFS('All Tickets (Master)'!$D$2:$D$227,$A10,'All Tickets (Master)'!$E$2:$E$227,$B10,'All Tickets (Master)'!$H$2:$H$227,"Reopened") -> 2 | I10: =COUNTIFS('All Tickets (Master)'!$D$2:$D$227,$A10,'All Tickets (Master)'!$E$2:$E$227,$B10,'All Tickets (Master)'!$G$2:$G$227,"Highest") -> 1 | J10: =COUNTIFS('All Tickets (Master)'!$D$2:$D$227,$A10,'All Tickets (Master)'!$E$2:$E$227,$B10,'All Tickets (Master)'!$G$2:$G$227,"High") -> 4 | K10: =COUNTIFS('All Tickets (Master)'!$D$2:$D$227,$A10,'All Tickets (Master)'!$E$2:$E$227,$B10,'All Tickets (Master)'!$G$2:$G$227,"Medium") -> 2 | L10: =COUNTIFS('All Tickets (Master)'!$D$2:$D$227,$A10,'All Tickets (Master)'!$E$2:$E$227,$B10,'All Tickets (Master)'!$G$2:$G$227,"Low") -> 1 | M10: =COUNTIFS('All Tickets (Master)'!$D$2:$D$227,$A10,'All Tickets (Master)'!$E$2:$E$227,$B10,'All Tickets (Master)'!$F$2:$F$227,"FE") -> 0 | N10: =COUNTIFS('All Tickets (Master)'!$D$2:$D$227,$A10,'All Tickets (Master)'!$E$2:$E$227,$B10,'All Tickets (Master)'!$F$2:$F$227,"BE") -> 2
A11: Brand | B11: Distributors | C11: =COUNTIFS('All Tickets (Master)'!$D$2:$D$227,$A11,'All Tickets (Master)'!$E$2:$E$227,$B11) -> 1 | D11: =COUNTIFS('All Tickets (Master)'!$D$2:$D$227,$A11,'All Tickets (Master)'!$E$2:$E$227,$B11,'All Tickets (Master)'!$H$2:$H$227,"Backlog") -> 0 | E11: =COUNTIFS('All Tickets (Master)'!$D$2:$D$227,$A11,'All Tickets (Master)'!$E$2:$E$227,$B11,'All Tickets (Master)'!$H$2:$H$227,"In Progress") -> 1 | F11: =COUNTIFS('All Tickets (Master)'!$D$2:$D$227,$A11,'All Tickets (Master)'!$E$2:$E$227,$B11,'All Tickets (Master)'!$H$2:$H$227,"In Staging") -> 0 | G11: =COUNTIFS('All Tickets (Master)'!$D$2:$D$227,$A11,'All Tickets (Master)'!$E$2:$E$227,$B11,'All Tickets (Master)'!$H$2:$H$227,"Ready for Production") -> 0 | H11: =COUNTIFS('All Tickets (Master)'!$D$2:$D$227,$A11,'All Tickets (Master)'!$E$2:$E$227,$B11,'All Tickets (Master)'!$H$2:$H$227,"Reopened") -> 0 | I11: =COUNTIFS('All Tickets (Master)'!$D$2:$D$227,$A11,'All Tickets (Master)'!$E$2:$E$227,$B11,'All Tickets (Master)'!$G$2:$G$227,"Highest") -> 1 | J11: =COUNTIFS('All Tickets (Master)'!$D$2:$D$227,$A11,'All Tickets (Master)'!$E$2:$E$227,$B11,'All Tickets (Master)'!$G$2:$G$227,"High") -> 0 | K11: =COUNTIFS('All Tickets (Master)'!$D$2:$D$227,$A11,'All Tickets (Master)'!$E$2:$E$227,$B11,'All Tickets (Master)'!$G$2:$G$227,"Medium") -> 0 | L11: =COUNTIFS('All Tickets (Master)'!$D$2:$D$227,$A11,'All Tickets (Master)'!$E$2:$E$227,$B11,'All Tickets (Master)'!$G$2:$G$227,"Low") -> 0 | M11: =COUNTIFS('All Tickets (Master)'!$D$2:$D$227,$A11,'All Tickets (Master)'!$E$2:$E$227,$B11,'All Tickets (Master)'!$F$2:$F$227,"FE") -> 0 | N11: =COUNTIFS('All Tickets (Master)'!$D$2:$D$227,$A11,'All Tickets (Master)'!$E$2:$E$227,$B11,'All Tickets (Master)'!$F$2:$F$227,"BE") -> 0
A12: Brand | B12: Retailers | C12: =COUNTIFS('All Tickets (Master)'!$D$2:$D$227,$A12,'All Tickets (Master)'!$E$2:$E$227,$B12) -> 3 | D12: =COUNTIFS('All Tickets (Master)'!$D$2:$D$227,$A12,'All Tickets (Master)'!$E$2:$E$227,$B12,'All Tickets (Master)'!$H$2:$H$227,"Backlog") -> 1 | E12: =COUNTIFS('All Tickets (Master)'!$D$2:$D$227,$A12,'All Tickets (Master)'!$E$2:$E$227,$B12,'All Tickets (Master)'!$H$2:$H$227,"In Progress") -> 1 | F12: =COUNTIFS('All Tickets (Master)'!$D$2:$D$227,$A12,'All Tickets (Master)'!$E$2:$E$227,$B12,'All Tickets (Master)'!$H$2:$H$227,"In Staging") -> 1 | G12: =COUNTIFS('All Tickets (Master)'!$D$2:$D$227,$A12,'All Tickets (Master)'!$E$2:$E$227,$B12,'All Tickets (Master)'!$H$2:$H$227,"Ready for Production") -> 0 | H12: =COUNTIFS('All Tickets (Master)'!$D$2:$D$227,$A12,'All Tickets (Master)'!$E$2:$E$227,$B12,'All Tickets (Master)'!$H$2:$H$227,"Reopened") -> 0 | I12: =COUNTIFS('All Tickets (Master)'!$D$2:$D$227,$A12,'All Tickets (Master)'!$E$2:$E$227,$B12,'All Tickets (Master)'!$G$2:$G$227,"Highest") -> 1 | J12: =COUNTIFS('All Tickets (Master)'!$D$2:$D$227,$A12,'All Tickets (Master)'!$E$2:$E$227,$B12,'All Tickets (Master)'!$G$2:$G$227,"High") -> 0 | K12: =COUNTIFS('All Tickets (Master)'!$D$2:$D$227,$A12,'All Tickets (Master)'!$E$2:$E$227,$B12,'All Tickets (Master)'!$G$2:$G$227,"Medium") -> 1 | L12: =COUNTIFS('All Tickets (Master)'!$D$2:$D$227,$A12,'All Tickets (Master)'!$E$2:$E$227,$B12,'All Tickets (Master)'!$G$2:$G$227,"Low") -> 1 | M12: =COUNTIFS('All Tickets (Master)'!$D$2:$D$227,$A12,'All Tickets (Master)'!$E$2:$E$227,$B12,'All Tickets (Master)'!$F$2:$F$227,"FE") -> 0 | N12: =COUNTIFS('All Tickets (Master)'!$D$2:$D$227,$A12,'All Tickets (Master)'!$E$2:$E$227,$B12,'All Tickets (Master)'!$F$2:$F$227,"BE") -> 2
A13: Brand | B13: Contacts | C13: =COUNTIFS('All Tickets (Master)'!$D$2:$D$227,$A13,'All Tickets (Master)'!$E$2:$E$227,$B13) -> 1 | D13: =COUNTIFS('All Tickets (Master)'!$D$2:$D$227,$A13,'All Tickets (Master)'!$E$2:$E$227,$B13,'All Tickets (Master)'!$H$2:$H$227,"Backlog") -> 1 | E13: =COUNTIFS('All Tickets (Master)'!$D$2:$D$227,$A13,'All Tickets (Master)'!$E$2:$E$227,$B13,'All Tickets (Master)'!$H$2:$H$227,"In Progress") -> 0 | F13: =COUNTIFS('All Tickets (Master)'!$D$2:$D$227,$A13,'All Tickets (Master)'!$E$2:$E$227,$B13,'All Tickets (Master)'!$H$2:$H$227,"In Staging") -> 0 | G13: =COUNTIFS('All Tickets (Master)'!$D$2:$D$227,$A13,'All Tickets (Master)'!$E$2:$E$227,$B13,'All Tickets (Master)'!$H$2:$H$227,"Ready for Production") -> 0 | H13: =COUNTIFS('All Tickets (Master)'!$D$2:$D$227,$A13,'All Tickets (Master)'!$E$2:$E$227,$B13,'All Tickets (Master)'!$H$2:$H$227,"Reopened") -> 0 | I13: =COUNTIFS('All Tickets (Master)'!$D$2:$D$227,$A13,'All Tickets (Master)'!$E$2:$E$227,$B13,'All Tickets (Master)'!$G$2:$G$227,"Highest") -> 0 | J13: =COUNTIFS('All Tickets (Master)'!$D$2:$D$227,$A13,'All Tickets (Master)'!$E$2:$E$227,$B13,'All Tickets (Master)'!$G$2:$G$227,"High") -> 0 | K13: =COUNTIFS('All Tickets (Master)'!$D$2:$D$227,$A13,'All Tickets (Master)'!$E$2:$E$227,$B13,'All Tickets (Master)'!$G$2:$G$227,"Medium") -> 1 | L13: =COUNTIFS('All Tickets (Master)'!$D$2:$D$227,$A13,'All Tickets (Master)'!$E$2:$E$227,$B13,'All Tickets (Master)'!$G$2:$G$227,"Low") -> 0 | M13: =COUNTIFS('All Tickets (Master)'!$D$2:$D$227,$A13,'All Tickets (Master)'!$E$2:$E$227,$B13,'All Tickets (Master)'!$F$2:$F$227,"FE") -> 0 | N13: =COUNTIFS('All Tickets (Master)'!$D$2:$D$227,$A13,'All Tickets (Master)'!$E$2:$E$227,$B13,'All Tickets (Master)'!$F$2:$F$227,"BE") -> 0
A14: Brand | B14: Pipeline | C14: =COUNTIFS('All Tickets (Master)'!$D$2:$D$227,$A14,'All Tickets (Master)'!$E$2:$E$227,$B14) -> 5 | D14: =COUNTIFS('All Tickets (Master)'!$D$2:$D$227,$A14,'All Tickets (Master)'!$E$2:$E$227,$B14,'All Tickets (Master)'!$H$2:$H$227,"Backlog") -> 5 | E14: =COUNTIFS('All Tickets (Master)'!$D$2:$D$227,$A14,'All Tickets (Master)'!$E$2:$E$227,$B14,'All Tickets (Master)'!$H$2:$H$227,"In Progress") -> 0 | F14: =COUNTIFS('All Tickets (Master)'!$D$2:$D$227,$A14,'All Tickets (Master)'!$E$2:$E$227,$B14,'All Tickets (Master)'!$H$2:$H$227,"In Staging") -> 0 | G14: =COUNTIFS('All Tickets (Master)'!$D$2:$D$227,$A14,'All Tickets (Master)'!$E$2:$E$227,$B14,'All Tickets (Master)'!$H$2:$H$227,"Ready for Production") -> 0 | H14: =COUNTIFS('All Tickets (Master)'!$D$2:$D$227,$A14,'All Tickets (Master)'!$E$2:$E$227,$B14,'All Tickets (Master)'!$H$2:$H$227,"Reopened") -> 0 | I14: =COUNTIFS('All Tickets (Master)'!$D$2:$D$227,$A14,'All Tickets (Master)'!$E$2:$E$227,$B14,'All Tickets (Master)'!$G$2:$G$227,"Highest") -> 0 | J14: =COUNTIFS('All Tickets (Master)'!$D$2:$D$227,$A14,'All Tickets (Master)'!$E$2:$E$227,$B14,'All Tickets (Master)'!$G$2:$G$227,"High") -> 3 | K14: =COUNTIFS('All Tickets (Master)'!$D$2:$D$227,$A14,'All Tickets (Master)'!$E$2:$E$227,$B14,'All Tickets (Master)'!$G$2:$G$227,"Medium") -> 1 | L14: =COUNTIFS('All Tickets (Master)'!$D$2:$D$227,$A14,'All Tickets (Master)'!$E$2:$E$227,$B14,'All Tickets (Master)'!$G$2:$G$227,"Low") -> 1 | M14: =COUNTIFS('All Tickets (Master)'!$D$2:$D$227,$A14,'All Tickets (Master)'!$E$2:$E$227,$B14,'All Tickets (Master)'!$F$2:$F$227,"FE") -> 0 | N14: =COUNTIFS('All Tickets (Master)'!$D$2:$D$227,$A14,'All Tickets (Master)'!$E$2:$E$227,$B14,'All Tickets (Master)'!$F$2:$F$227,"BE") -> 0
A15: Brand | B15: Trade Spend Sandbox | C15: =COUNTIFS('All Tickets (Master)'!$D$2:$D$227,$A15,'All Tickets (Master)'!$E$2:$E$227,$B15) -> 37 | D15: =COUNTIFS('All Tickets (Master)'!$D$2:$D$227,$A15,'All Tickets (Master)'!$E$2:$E$227,$B15,'All Tickets (Master)'!$H$2:$H$227,"Backlog") -> 28 | E15: =COUNTIFS('All Tickets (Master)'!$D$2:$D$227,$A15,'All Tickets (Master)'!$E$2:$E$227,$B15,'All Tickets (Master)'!$H$2:$H$227,"In Progress") -> 1 | F15: =COUNTIFS('All Tickets (Master)'!$D$2:$D$227,$A15,'All Tickets (Master)'!$E$2:$E$227,$B15,'All Tickets (Master)'!$H$2:$H$227,"In Staging") -> 3 | G15: =COUNTIFS('All Tickets (Master)'!$D$2:$D$227,$A15,'All Tickets (Master)'!$E$2:$E$227,$B15,'All Tickets (Master)'!$H$2:$H$227,"Ready for Production") -> 4 | H15: =COUNTIFS('All Tickets (Master)'!$D$2:$D$227,$A15,'All Tickets (Master)'!$E$2:$E$227,$B15,'All Tickets (Master)'!$H$2:$H$227,"Reopened") -> 1 | I15: =COUNTIFS('All Tickets (Master)'!$D$2:$D$227,$A15,'All Tickets (Master)'!$E$2:$E$227,$B15,'All Tickets (Master)'!$G$2:$G$227,"Highest") -> 5 | J15: =COUNTIFS('All Tickets (Master)'!$D$2:$D$227,$A15,'All Tickets (Master)'!$E$2:$E$227,$B15,'All Tickets (Master)'!$G$2:$G$227,"High") -> 21 | K15: =COUNTIFS('All Tickets (Master)'!$D$2:$D$227,$A15,'All Tickets (Master)'!$E$2:$E$227,$B15,'All Tickets (Master)'!$G$2:$G$227,"Medium") -> 5 | L15: =COUNTIFS('All Tickets (Master)'!$D$2:$D$227,$A15,'All Tickets (Master)'!$E$2:$E$227,$B15,'All Tickets (Master)'!$G$2:$G$227,"Low") -> 6 | M15: =COUNTIFS('All Tickets (Master)'!$D$2:$D$227,$A15,'All Tickets (Master)'!$E$2:$E$227,$B15,'All Tickets (Master)'!$F$2:$F$227,"FE") -> 2 | N15: =COUNTIFS('All Tickets (Master)'!$D$2:$D$227,$A15,'All Tickets (Master)'!$E$2:$E$227,$B15,'All Tickets (Master)'!$F$2:$F$227,"BE") -> 1
... A31: Platform & Cross-Cutting | B31: Infrastructure / Cross-Cutting | C31: =COUNTIFS('All Tickets (Master)'!$D$2:$D$227,$A31,'All Tickets (Master)'!$E$2:$E$227,$B31) -> 28 | D31: =COUNTIFS('All Tickets (Master)'!$D$2:$D$227,$A31,'All Tickets (Master)'!$E$2:$E$227,$B31,'All Tickets (Master)'!$H$2:$H$227,"Backlog") -> 22 | E31: =COUNTIFS('All Tickets (Master)'!$D$2:$D$227,$A31,'All Tickets (Master)'!$E$2:$E$227,$B31,'All Tickets (Master)'!$H$2:$H$227,"In Progress") -> 4 | F31: =COUNTIFS('All Tickets (Master)'!$D$2:$D$227,$A31,'All Tickets (Master)'!$E$2:$E$227,$B31,'All Tickets (Master)'!$H$2:$H$227,"In Staging") -> 0 | G31: =COUNTIFS('All Tickets (Master)'!$D$2:$D$227,$A31,'All Tickets (Master)'!$E$2:$E$227,$B31,'All Tickets (Master)'!$H$2:$H$227,"Ready for Production") -> 1 | H31: =COUNTIFS('All Tickets (Master)'!$D$2:$D$227,$A31,'All Tickets (Master)'!$E$2:$E$227,$B31,'All Tickets (Master)'!$H$2:$H$227,"Reopened") -> 1 | I31: =COUNTIFS('All Tickets (Master)'!$D$2:$D$227,$A31,'All Tickets (Master)'!$E$2:$E$227,$B31,'All Tickets (Master)'!$G$2:$G$227,"Highest") -> 2 | J31: =COUNTIFS('All Tickets (Master)'!$D$2:$D$227,$A31,'All Tickets (Master)'!$E$2:$E$227,$B31,'All Tickets (Master)'!$G$2:$G$227,"High") -> 14 | K31: =COUNTIFS('All Tickets (Master)'!$D$2:$D$227,$A31,'All Tickets (Master)'!$E$2:$E$227,$B31,'All Tickets (Master)'!$G$2:$G$227,"Medium") -> 6 | L31: =COUNTIFS('All Tickets (Master)'!$D$2:$D$227,$A31,'All Tickets (Master)'!$E$2:$E$227,$B31,'All Tickets (Master)'!$G$2:$G$227,"Low") -> 6 | M31: =COUNTIFS('All Tickets (Master)'!$D$2:$D$227,$A31,'All Tickets (Master)'!$E$2:$E$227,$B31,'All Tickets (Master)'!$F$2:$F$227,"FE") -> 1 | N31: =COUNTIFS('All Tickets (Master)'!$D$2:$D$227,$A31,'All Tickets (Master)'!$E$2:$E$227,$B31,'All Tickets (Master)'!$F$2:$F$227,"BE") -> 4
B32: GRAND TOTAL | C32: =SUM(C4:C31) -> 225 | D32: =SUM(D4:D31) -> 181 | E32: =SUM(E4:E31) -> 21 | F32: =SUM(F4:F31) -> 6 | G32: =SUM(G4:G31) -> 8 | H32: =SUM(H4:H31) -> 9 | I32: =SUM(I4:I31) -> 30 | J32: =SUM(J4:J31) -> 111 | ... N32: =SUM(N4:N31) -> 29

Sheet All Tickets (Master)
A1: Issue Key | B1: Type | C1: Summary | D1: Area | E1: Caboodle Module | F1: FE/BE | G1: Priority | H1: Status | I1: Assignee | J1: Reporter | K1: Created | L1: Updated | M1: Due / Note
A2: CS-146 | B2: Task | C2: [BE] Module on off | D2: Admin | E2: Admin (General) | F2: BE | G2: Medium | H2: Backlog | I2: Bijoy Chandra Nath | J2: Md Mashiul Azam Chowdhury | K2: 12/3/2023 | L2: 12/3/2023 | M2: Discuss
A3: CS-147 | B3: Task | C3: [FE] Module on off | D3: Admin | E3: Admin (General) | F3: FE | G3: Medium | H3: Backlog | I3: Md Mashiul Azam Chowdhury | J3: Md Mashiul Azam Chowdhury | K3: 12/3/2023 | L3: 4/27/2025 | M3: Discuss
A4: CS-190 | B4: Task | C4: Caboodle Phase 2 Requirements | D4: Platform & Cross-Cutting | E4: Infrastructure / Cross-Cutting | F4: Unspec | G4: Medium | H4: Backlog | J4: Md Mashiul Azam Chowdhury | K4: 12/9/2023 | L4: 2/5/2024
A5: CS-234 | B5: Task | C5: [BE] Promotional Management - Push date submission to brand side | D5: Broker Dashboard | E5: Promotional Management | F5: BE | G5: Medium | H5: Backlog | I5: Bijoy Chandra Nath | J5: Md Mashiul Azam Chowdhury | K5: 12/21/2023 | L5: 12/21/2023 | M5: Discuss
A6: CS-232 | B6: Task | C6: [BE] Promotional Management - Published distributor pricing for Promo Submissions | D6: Broker Dashboard | E6: Promotional Management | F6: BE | G6: Low | H6: Backlog | I6: Bijoy Chandra Nath | J6: Md Mashiul Azam Chowdhury | K6: 12/21/2023 | L6: 12/21/2023 | M6: Discuss
A7: CS-245 | B7: Task | C7: [BE] Admin - Activity Log | D7: Admin | E7: Admin (General) | F7: BE | G7: Low | H7: Backlog | I7: Bijoy Chandra Nath | J7: Md Mashiul Azam Chowdhury | K7: 12/21/2023 | L7: 12/21/2023 | M7: Discuss
A8: CS-246 | B8: Task | C8: [FE] Admin - Activity Log | D8: Admin | E8: Admin (General) | F8: FE | G8: Low | H8: Backlog | I8: Md Mashiul Azam Chowdhury | J8: Md Mashiul Azam Chowdhury | K8: 12/21/2023 | L8: 4/27/2025 | M8: Discuss
A9: CS-247 | B9: Task | C9: [BE] Admin - Upload Effeciency | D9: Admin | E9: Admin (General) | F9: BE | G9: Low | H9: Backlog | I9: Bijoy Chandra Nath | J9: Md Mashiul Azam Chowdhury | K9: 12/21/2023 | L9: 12/21/2023 | M9: Discuss
A10: CS-280 | B10: Task | C10: [BE] Product Specs Add a text box for Shelf Life and another for Attributes. Doesn't need to be in the file upload | D10: Brand | E10: Product Specs | F10: BE | G10: Medium | H10: Backlog | I10: Bijoy Chandra Nath | J10: Md Mashiul Azam Chowdhury | K10: 1/1/2024 | L10: 1/1/2024 | M10: Don't Do
A11: CS-376 | B11: Task | C11: Product Specs - Add Chck Box for Manufacturer Discontinued | D11: Brand | E11: Product Specs | F11: Unspec | G11: Medium | H11: Backlog | I11: Md Mashiul Azam Chowdhury | J11: Constance Wolfe | K11: 2/10/2024 | L11: 4/27/2025 | M11: Complete?
A12: CS-405 | B12: Task | C12: Monitoring Service | D12: Platform & Cross-Cutting | E12: Infrastructure / Cross-Cutting | F12: Unspec | G12: Medium | H12: Backlog | I12: Bijoy Chandra Nath | J12: Bijoy Chandra Nath | K12: 2/29/2024 | L12: 9/25/2025 | M12: ??
A13: CS-478 | B13: Bug | C13: Product Specs Price List | Price Change is not flowing thru Trade Spend for promos after date change | D13: Brand | E13: Product Specs | F13: Unspec | G13: Highest | H13: Reopened | I13: Bijoy Chandra Nath | J13: Constance Wolfe | K13: 4/25/2024 | L13: 7/9/2024
A14: CS-487 | B14: Task | C14: [BE] Saving Banner SKU Failed Records and automatically adding them back into the system once we've matched up the unrecognized banners from the Data Mapping section | D14: Admin | E14: Data Mapping | F14: BE | G14: Medium | H14: Backlog | I14: Bijoy Chandra Nath | J14: Bijoy Chandra Nath | K14: 4/29/2024 | L14: 9/25/2025 | M14: ??
A15: CS-496 | B15: Bug | C15: Banner Upload Error Messaging | D15: Admin | E15: CRM Data Upload | F15: Unspec | G15: High | H15: Backlog | J15: Constance Wolfe | K15: 5/2/2024 | L15: 11/10/2025 | M15: ??
A16: CS-514 | B16: Task | C16: Optimize the tables to ensure that the site remains unaffected even with a large amount of data. | D16: Platform & Cross-Cutting | E16: Infrastructure / Cross-Cutting | F16: Unspec | G16: High | H16: Backlog | I16: Md Mashiul Azam Chowdhury | J16: Md Mashiul Azam Chowdhury | K16: 5/7/2024 | L16: 5/7/2024 | M16: Complete?
A17: CS-517 | B17: Task | C17: Apply Indexing Mechanism in Database | D17: Platform & Cross-Cutting | E17: Infrastructure / Cross-Cutting | F17: Unspec | G17: High | H17: In Progress | I17: Bijoy Chandra Nath | J17: Bijoy Chandra Nath | K17: 5/7/2024 | L17: 9/25/2025 | M17: Provide update
A18: CS-512 | B18: Task | C18: Check if we can further utilize caching from any other areas | D18: Platform & Cross-Cutting | E18: Infrastructure / Cross-Cutting | F18: Unspec | G18: Medium | H18: Backlog | I18: Md Mashiul Azam Chowdhury | J18: Md Mashiul Azam Chowdhury | K18: 5/7/2024 | L18: 5/7/2024 | M18: ??
A19: CS-518 | B19: Task | C19: Automatically Remove Deleted Records After Certain Period Of Time | D19: Platform & Cross-Cutting | E19: Infrastructure / Cross-Cutting | F19: Unspec | G19: Medium | H19: Backlog | I19: Bijoy Chandra Nath | J19: Bijoy Chandra Nath | K19: 5/7/2024 | L19: 9/25/2025 | M19: ??
A20: CS-519 | B20: Task | C20: [BE] Re-Structuring The Code Base | D20: Platform & Cross-Cutting | E20: Infrastructure / Cross-Cutting | F20: BE | G20: Medium | H20: In Progress | I20: Bijoy Chandra Nath | J20: Bijoy Chandra Nath | K20: 5/7/2024 | L20: 9/25/2025 | M20: Provide update
A21: CS-532 | B21: Task | C21: Trade Spend | Promo Event Details | Is it possible to add a sku without going thru the stepper again? | D21: Brand | E21: Trade Spend Sandbox | F21: Unspec | G21: Low | H21: Backlog | J21: Constance Wolfe | K21: 5/28/2024 | L21: 5/28/2024 | M21: Complete?
A22: CS-562 | B22: Task | C22: [BE] Implement User-Based Permission Control Module | D22: Admin | E22: User Management | F22: BE | G22: Medium | H22: In Progress | I22: Bijoy Chandra Nath | J22: Bijoy Chandra Nath | K22: 6/24/2024 | L22: 9/25/2025 | M22: Provide update
A23: CS-570 | B23: Task | C23: Filters Updates | D23: Platform & Cross-Cutting | E23: Infrastructure / Cross-Cutting | F23: Unspec | G23: Highest | H23: Reopened | I23: Md Mashiul Azam Chowdhury | J23: Heather Whittier | K23: 7/9/2024 | L23: 4/27/2025
A24: CS-617 | B24: Sub-task | C24: [BE] Manufacture Discontinue | MFR Disco Status | D24: Brand | E24: Product Specs | F24: BE | G24: High | H24: In Progress | I24: Bijoy Chandra Nath | J24: Md Mashiul Azam Chowdhury | K24: 9/26/2024 | L24: 1/7/2025 | M24: Provide update
A25: CS-653 | B25: Task | C25: Caboodle Broker | Trade Spend Sandbox should report to Promotional Management (not Promo Planning) | D25: Brand | E25: Trade Spend Sandbox | F25: Unspec | G25: High | H25: Ready for Production | I25: Bijoy Chandra Nath | J25: Constance Wolfe | K25: 11/26/2024 | L25: 11/6/2025 | M25: Provide update
A26: CS-658 | B26: Bug | C26: Files | Files Tree Display issues See image of overlapping folders | D26: Broker Dashboard | E26: Files | F26: Unspec | G26: High | H26: Backlog | I26: Md Mashiul Azam Chowdhury | J26: Constance Wolfe | K26: 12/6/2024 | L26: 4/27/2025 | M26: ??
A27: CS-675 | B27: Sub-task | C27: Empowering Brand owner's edit in Banner SKU section | D27: Admin | E27: Admin (General) | F27: Unspec | G27: High | H27: Backlog | I27: Bijoy Chandra Nath | J27: Md Mashiul Azam Chowdhury | K27: 12/26/2024 | L27: 9/25/2025 | M27: ??
A28: CS-688 | B28: Task | C28: [BE] Implement read tables for Market Overview | D28: Broker Dashboard | E28: Market Overview | F28: BE | G28: High | H28: In Progress | I28: Bijoy Chandra Nath | J28: Bijoy Chandra Nath | K28: 2/5/2025 | L28: 9/25/2025 | M28: Provide update
A29: CS-701 | B29: Story | C29: Share link of pages like in google and restrict it to view only | D29: Platform & Cross-Cutting | E29: Infrastructure / Cross-Cutting | F29: Unspec | G29: Low | H29: Backlog | I29: Constance Wolfe | J29: Md Mashiul Azam Chowdhury | K29: 2/17/2025 | L29: 11/6/2025 | M29: ??
A30: CS-725 | B30: Story | C30: Trade Spend Promotion Module | D30: Brand | E30: Trade Spend Sandbox | F30: Unspec | G30: Highest | H30: Backlog | I30: Md Mashiul Azam Chowdhury | J30: Bijoy Chandra Nath | K30: 3/12/2025 | L30: 3/12/2025 | M30: ??
A31: CS-894 | B31: Epic | C31: Issues from QA audit | D31: Platform & Cross-Cutting | E31: Infrastructure / Cross-Cutting | F31: QA | G31: Low | H31: Backlog | J31: Fariha Jabin | K31: 5/5/2025 | L31: 11/6/2025 | M31: ??
A32: CS-955 | B32: Epic | C32: UX Audit | D32: Platform & Cross-Cutting | E32: Infrastructure / Cross-Cutting | F32: Unspec | G32: High | H32: Backlog | I32: Abdullah Al Mahmud | J32: Md Mashiul Azam Chowdhury | K32: 5/15/2025 | L32: 11/6/2025 | M32: ??
A33: CS-973 | B33: Story | C33: Regression Test | D33: Platform & Cross-Cutting | E33: Infrastructure / Cross-Cutting | F33: QA | G33: Low | H33: Backlog | J33: Fariha Jabin | K33: 5/26/2025 | L33: 5/29/2025 | M33: ??
A34: CS-992 | B34: Sub-task | C34: [BE] Retailer details page - Category search returning irrelevant results | D34: Brand | E34: Retailers | F34: BE | G34: Low | H34: In Progress | I34: Bijoy Chandra Nath | J34: Fariha Jabin | K34: 6/4/2025 | L34: 9/25/2025 | M34: Provide update
A35: CS-1022 | B35: Bug | C35: Trade Spend Sandbox | Step 2 Category Issues | D35: Brand | E35: Trade Spend Sandbox | F35: Unspec | G35: High | H35: Reopened | I35: Md Mashiul Azam Chowdhury | J35: Constance Wolfe | K35: 6/21/2025 | L35: 11/10/2025
A36: CS-1032 | B36: Task | C36: [BE] Reports > Promoted Case Allowance -Please start | D36: Reports | E36: Reports (Unspecified) | F36: BE | G36: High | H36: In Progress | I36: Bijoy Chandra Nath | J36: Constance Wolfe | K36: 7/1/2025 | L36: 9/25/2025 | M36: Q1
A37: CS-1037 | B37: Bug | C37: [BE] No error message when uploading a blank file | D37: Admin | E37: CRM Data Upload | F37: BE | G37: Low | H37: Backlog | I37: Bijoy Chandra Nath | J37: Fariha Jabin | K37: 7/1/2025 | L37: 11/10/2025 | M37: Q1
A38: CS-1042 | B38: Bug | C38: banner edit modal  sometimes retailer name shows retailer id | D38: Admin | E38: CRM Data Upload | F38: Unspec | G38: Low | H38: Reopened | I38: Md Mashiul Azam Chowdhury | J38: Fariha Jabin | K38: 7/1/2025 | L38: 11/17/2025
A39: CS-1038 | B39: Bug | C39: [BE] Template files dont show required/mandatory fields | D39: Admin | E39: Admin (General) | F39: BE | G39: High | H39: Backlog | I39: Bijoy Chandra Nath | J39: Fariha Jabin | K39: 7/1/2025 | L39: 11/10/2025 | M39: Q1
A40: CS-1039 | B40: Bug | C40: [BE] Field mismatch between manual form and upload template | D40: Admin | E40: Admin (General) | F40: BE | G40: Medium | H40: Backlog | I40: Bijoy Chandra Nath | J40: Fariha Jabin | K40: 7/1/2025 | L40: 11/10/2025 | M40: Fixed?
...

Sheet Broker Dashboard
A1: Broker Dashboard — 33 tickets
A3: Issue Key | B3: Type | C3: Summary | D3: Area | E3: Caboodle Module | F3: FE/BE | G3: Priority | H3: Status | I3: FE | J3: BE | K3: QA | L3: Assignee | M3: Reporter | N3: Created | O3: Updated | P3: Due / Note
A4: ▸ Market Overview (6)
A5: CS-1299 | C5: Broker Dashboard Updates > APL + Add Log Market Overview | D5: Broker Dashboard | E5: Market Overview | F5: Unspec | G5: High | H5: Backlog | L5: Md Mashiul Azam Chowdhury Efti | M5: Constance Wolfe | N5: 3/31/2026 | O5: 5/4/2026 | P5: STORY 1326
C6: Moved to Brand Mondule (Home Page)
A7: CS-1310 | C7: Broker Dashboard Market Overview > Store List Not populating | D7: Broker Dashboard | E7: Market Overview | F7: Unspec | G7: High | H7: Backlog | I7: 30m | J7: 1h | K7: 30m | L7: Bijoy Chandra Nath | M7: Constance Wolfe | N7: 3/31/2026 | O7: 5/4/2026 | P7: STORY 1326
A8: CS-1318 | C8: Broker Dashboard | Market Overview Filter Needs more Field Options List Too Limited | D8: Broker Dashboard | E8: Market Overview | F8: Unspec | G8: High | H8: Backlog | I8: 3h | J8: 2h | K8: 1h | L8: Bijoy Chandra Nath | M8: Constance Wolfe | N8: 4/2/2026 | O8: 5/4/2026 | P8: STORY 1326
A9: CS-1326 | C9: Enhance Broker Dashboard Market Overview Functionality | D9: Broker Dashboard | E9: Market Overview | F9: Unspec | G9: High | H9: Backlog | L9: Md Mashiul Azam Chowdhury Efti | M9: Md Mashiul Azam Chowdhury Efti | N9: 4/7/2026 | O9: 5/4/2026 | P9: STORY
A10: CS-688 | B10: Task | C10: [BE] Implement read tables for Market Overview | D10: Broker Dashboard | E10: Market Overview | F10: BE | G10: High | H10: In Progress | J10: 4h | K10: 2h | L10: Bijoy Chandra Nath | M10: Bijoy Chandra Nath | N10: 2/5/2025 | O10: 9/25/2025 | P10: Provide update
A11: ▸ Promotional Management (5)
A12: CS-1324 | C12: Broker Dashboard | Promotional Management Only push Brand Approved Promotions to Promo Management | D12: Broker Dashboard | E12: Promotional Management | F12: Unspec | G12: High | H12: Backlog | J12: 2h | K12: 1h | L12: Bijoy Chandra Nath | M12: Constance Wolfe | N12: 4/3/2026 | O12: 5/4/2026 | P12: STORY 1328
A13: CS-1328 | C13: Improve Broker Promotional Management Export and Approval Flow | D13: Broker Dashboard | E13: Promotional Management | F13: Unspec | G13: High | H13: Backlog | L13: Md Mashiul Azam Chowdhury Efti | M13: Md Mashiul Azam Chowdhury Efti | N13: 4/7/2026 | O13: 5/4/2026 | P13: STORY
A14: CS-1367 | C14: Broker Dashboard Promo Management | Export Data Does not Match Filter Data (Does not work at all) | D14: Broker Dashboard | E14: Promotional Management | F14: Unspec | G14: High | H14: Backlog | J14: 3h | K14: 1h | L14: Md Mashiul Azam Chowdhury Efti | M14: Constance Wolfe | N14: 5/2/2026 | O14: 5/2/2026
A15: CS-234 | B15: Task | C15: [BE] Promotional Management - Push date submission to brand side | D15: Broker Dashboard | E15: Promotional Management | F15: BE | G15: Medium | H15: Backlog | L15: Bijoy Chandra Nath | M15: Md Mashiul Azam Chowdhury | N15: 12/21/2023 | O15: 12/21/2023
A16: CS-232 | B16: Task | C16: [BE] Promotional Management - Published distributor pricing for Promo Submissions | D16: Broker Dashboard | E16: Promotional Management | F16: BE | G16: Low | H16: Backlog | L16: Bijoy Chandra Nath | M16: Md Mashiul Azam Chowdhury | N16: 12/21/2023 | O16: 12/21/2023
A17: ▸ Category Review (11)
A18: CS-1417 | B18: In Staging | C18: Broker Dashboard | Category Review Filter & Upload Issues | D18: Broker Dashboard | E18: Category Review | F18: Unspec | G18: Highest | H18: Backlog | L18: Bijoy Chandra Nath | M18: Constance Wolfe | N18: 5/30/2026 | O18: 6/4/2026
A19: CS-1296 | B19: Done | C19: Broker Dashboard | Category Review Calendar Rollup | D19: Broker Dashboard | E19: Category Review | F19: Unspec | G19: High | H19: Backlog | L19: Bijoy Chandra Nath | M19: Constance Wolfe | N19: 3/31/2026 | O19: 5/28/2026 | P19: STORY 1327
A20: CS-1315 | B20: Done | C20: Category Review | Export All Data only Exports the current Page | D20: Broker Dashboard | E20: Category Review | F20: Unspec | G20: High | H20: In Progress | L20: Bijoy Chandra Nath | M20: Constance Wolfe | N20: 4/2/2026 | O20: 5/5/2026 | P20: STORY 1330
A21: CS-1316 | C21: Category Review | Implement Scrolling vs pages | D21: Broker Dashboard | E21: Category Review | F21: Unspec | G21: High | H21: Backlog | I21: 2h | K21: 10m | L21: Md Mashiul Azam Chowdhury Efti | M21: Constance Wolfe | N21: 4/2/2026 | O21: 5/4/2026 | P21: STORY 1330
A22: CS-1317 | B22: Redundend | C22: Category Review | UI/UX Consider more modern look/feel See sample | D22: Broker Dashboard | E22: Category Review | F22: Unspec | G22: High | H22: Backlog | L22: Md Mashiul Azam Chowdhury Efti | M22: Constance Wolfe | N22: 4/2/2026 | O22: 5/4/2026 | P22: STORY 1330 This Example is a Loveable Design for a new functionality
A23: CS-1319 | B23: Done | C23: Category Review | Adding Retailers with multiple Reviews Produces Duplicates of the Retailer in the Filter (Also see CS-1320) | D23: Broker Dashboard | E23: Category Review | F23: Unspec | G23: High | H23: Backlog | L23: Md Mashiul Azam Chowdhury Efti | M23: Constance Wolfe | N23: 4/3/2026 | O23: 4/3/2026
A24: CS-1320 | B24: Done | C24: Category Review | Add Log Error Invalid Month Even though the month is Valid | D24: Broker Dashboard | E24: Category Review | F24: Unspec | G24: High | H24: Reopened | L24: Bijoy Chandra Nath | M24: Constance Wolfe | N24: 4/3/2026 | O24: 5/18/2026
A25: CS-1329 | C25: Fix Category Review Data Isolation and Upload Issues | D25: Broker Dashboard | E25: Category Review | F25: Unspec | G25: High | H25: Backlog | L25: Bijoy Chandra Nath | M25: Md Mashiul Azam Chowdhury Efti | N25: 4/7/2026 | O25: 5/4/2026
A26: CS-1330 | C26: Improve Category Review UX, Navigation and Export | D26: Broker Dashboard | E26: Category Review | F26: Unspec | G26: High | H26: Backlog | L26: Md Mashiul Azam Chowdhury Efti | M26: Md Mashiul Azam Chowdhury Efti | N26: 4/7/2026 | O26: 5/4/2026 | P26: STORY
A27: CS-1361 | B27: Redundend | C27: Broker Dashboard | New Category Review Functionality | D27: Broker Dashboard | E27: Category Review | F27: Unspec | G27: High | H27: Backlog | L27: Bijoy Chandra Nath | M27: Constance Wolfe | N27: 4/29/2026 | O27: 6/17/2026 | P27: SEE Ticket 1317
A28: CS-1423 | B28: Done | C28: Broker Dashboard | Category Review Propagation | D28: Broker Dashboard | E28: Category Review | F28: Unspec | G28: High | H28: Backlog | L28: Bijoy Chandra Nath | M28: Constance Wolfe | N28: 6/20/2026 | O28: 6/21/2026
A29: ▸ Distributor APL (4)
A30: CS-1424 | B30: Task | C30: Data Mapping | Broker Dashboard APL | Need Data Sync for Broker Distributor APL | D30: Broker Dashboard | E30: Distributor APL | F30: Unspec | G30: Highest | H30: Backlog | I30: 2h | J30: 6d | L30: Md Mashiul Azam Chowdhury Efti | M30: Constance Wolfe | N30: 6/23/2026 | O30: 6/23/2026
A31: CS-1363 | C31: Broker Dashboard | APL Add Distributor & Product (make dependent to brand) to the Filter | D31: Broker Dashboard | E31: Distributor APL | F31: Unspec | G31: High | H31: Backlog | I31: 2h | J31: 4h | K31: 1h | L31: Md Mashiul Azam Chowdhury Efti | M31: Constance Wolfe | N31: 4/29/2026 | O31: 4/29/2026
A32: CS-1403 | C32: Broker Dashboard | APL Upload Adjust for UNFI UPC Codes | D32: Broker Dashboard | E32: Distributor APL | F32: Unspec | G32: High | H32: Backlog | J32: 4h | K32: 1h | L32: Md Mashiul Azam Chowdhury Efti | M32: Constance Wolfe | N32: 5/13/2026 | O32: 5/13/2026
A33: CS-1408 | C33: Broker Dashboard > APL Report > Filter showing multiple listings for same item | D33: Broker Dashboard | E33: Distributor APL | F33: Unspec | G33: High | H33: Backlog | J33: CS-1363 | L33: Md Mashiul Azam Chowdhury Efti | M33: Constance Wolfe | N33: 5/20/2026 | O33: 5/20/2026
A34: ▸ Files (3)
A35: CS-1159 | B35: Bug | C35: Folders | Download causing Errors | D35: Broker Dashboard | E35: Files | F35: Unspec | G35: Highest | H35: Backlog | L35: Bijoy Chandra Nath | M35: Constance Wolfe | N35: 9/8/2025 | O35: 11/10/2025 | P35: See Ticket 1179
A36: CS-1179 | B36: Bug | C36: Files | Downloads still have errors see details | D36: Broker Dashboard | E36: Files | F36: Unspec | G36: Highest | H36: Backlog | L36: Md Mashiul Azam Chowdhury | M36: Constance Wolfe | N36: 9/26/2025 | O36: 11/10/2025 | P36: Q1
A37: CS-658 | B37: Bug | C37: Files | Files Tree Display issues See image of overlapping folders | D37: Broker Dashboard | E37: Files | F37: Unspec | G37: High | H37: Backlog | I37: 4h | K37: 30m | L37: Md Mashiul Azam Chowdhury | M37: Constance Wolfe | N37: 12/6/2024 | O37: 4/27/2025 | P37: ??
A38: ▸ Broker Dashboard (General) (4)
A39: CS-1072 | B39: Task | C39: [BE] Broker Dashboard> Update landing page to match Brand environments. Replace dashboard with Broker Logo | D39: Broker Dashboard | E39: Broker Dashboard (General) | F39: BE | G39: High | H39: Backlog | L39: Bijoy Chandra Nath | M39: Constance Wolfe | N39: 7/15/2025 | O39: 11/6/2025 | P39: Q2/Q3
A40: CS-1305 | C40: Broker Dashboard Update UI to match the rest of the platform | D40: Broker Dashboard | E40: Broker Dashboard (General) | F40: Unspec | G40: High | H40: Backlog | L40: Md Mashiul Azam Chowdhury Efti | M40: Constance Wolfe | N40: 3/31/2026 | O40: 3/31/2026
A41: CS-1327 | C41: Fix Broker Dashboard Navigation and UI Issues | D41: Broker Dashboard | E41: Broker Dashboard (General) | F41: Unspec | G41: High | H41: Backlog | L41: Bijoy Chandra Nath | M41: Md Mashiul Azam Chowdhury Efti | N41: 4/7/2026 | O41: 5/4/2026
...

Sheet Brand Modules
A1: Brand — 56 tickets
A3: Issue Key | B3: Type | C3: Summary | D3: Area | E3: Caboodle Module | F3: FE/BE | G3: Priority | H3: Status | I3: Assignee | J3: Reporter | K3: Created | L3: Updated | M3: Due / Note
A4: ▸ Product Specs (8)
A5: CS-478 | B5: Bug | C5: Product Specs Price List | Price Change is not flowing thru Trade Spend for promos after date change | D5: Brand | E5: Product Specs | F5: Unspec | G5: Highest | H5: Reopened | I5: Bijoy Chandra Nath | J5: Constance Wolfe | K5: 4/25/2024 | L5: 7/9/2024
A6: CS-1077 | B6: Task | C6: Product Specs Add Product Change Order & Names of Fields | D6: Brand | E6: Product Specs | F6: Unspec | G6: High | H6: Backlog | I6: Md Mashiul Azam Chowdhury | J6: Constance Wolfe | K6: 7/22/2025 | L6: 7/22/2025 | M6: Q2
A7: CS-1386 | C7: Product Specs | Reorganize Tabs to this order: Categories > Products > Pricing | D7: Brand | E7: Product Specs | F7: Unspec | G7: High | H7: Backlog | I7: Md Mashiul Azam Chowdhury Efti | J7: Constance Wolfe | K7: 5/11/2026 | L7: 5/11/2026 | M7: Complete
A8: CS-1400 | C8: Product Specs | Updating Spec UPC Code causing Error | D8: Brand | E8: Product Specs | F8: Unspec | G8: High | H8: Backlog | I8: Md Mashiul Azam Chowdhury Efti | J8: Constance Wolfe | K8: 5/13/2026 | L8: 5/13/2026
A9: CS-617 | B9: Sub-task | C9: [BE] Manufacture Discontinue | MFR Disco Status | D9: Brand | E9: Product Specs | F9: BE | G9: High | H9: In Progress | I9: Bijoy Chandra Nath | J9: Md Mashiul Azam Chowdhury | K9: 9/26/2024 | L9: 1/7/2025 | M9: Provide update
A10: CS-280 | B10: Task | C10: [BE] Product Specs Add a text box for Shelf Life and another for Attributes. Doesn't need to be in the file upload | D10: Brand | E10: Product Specs | F10: BE | G10: Medium | H10: Backlog | I10: Bijoy Chandra Nath | J10: Md Mashiul Azam Chowdhury | K10: 1/1/2024 | L10: 1/1/2024 | M10: Don't Do
A11: CS-376 | B11: Task | C11: Product Specs - Add Chck Box for Manufacturer Discontinued | D11: Brand | E11: Product Specs | F11: Unspec | G11: Medium | H11: Backlog | I11: Md Mashiul Azam Chowdhury | J11: Constance Wolfe | K11: 2/10/2024 | L11: 4/27/2025 | M11: Complete?
A12: CS-1112 | B12: Task | C12: product category change causes pricing to show "pricing not set" | D12: Brand | E12: Product Specs | F12: Unspec | G12: Low | H12: Reopened | I12: Bijoy Chandra Nath | J12: Fariha Jabin | K12: 8/14/2025 | L12: 11/6/2025
A13: ▸ Distributors (1)
A14: CS-1225 | B14: Task | C14: CRM > Distributor > Unlink Banner > Remove restriction that it's tied up in a Promotion | D14: Brand | E14: Distributors | F14: Unspec | G14: Highest | H14: In Progress | I14: Bijoy Chandra Nath | J14: Constance Wolfe | K14: 11/8/2025 | L14: 11/11/2025 | M14: Provide Update
A15: ▸ Retailers (3)
A16: CS-1211 | B16: Task | C16: [BE] CRM - Retailers> Banner Activities Newest Dates at the top of the list | D16: Brand | E16: Retailers | F16: BE | G16: Highest | H16: In Staging | I16: Bijoy Chandra Nath | J16: Bijoy Chandra Nath | K16: 11/4/2025 | L16: 11/5/2025 | M16: Provide Update
A17: CS-1199 | B17: Bug | C17: CRM> Retailers>Promo $Rules> Upload option doesn't work> Other Notes in Description | D17: Brand | E17: Retailers | F17: Unspec | G17: Medium | H17: Backlog | I17: Md Mashiul Azam Chowdhury | J17: Constance Wolfe | K17: 10/23/2025 | L17: 11/10/2025 | M17: Q2
A18: CS-992 | B18: Sub-task | C18: [BE] Retailer details page - Category search returning irrelevant results | D18: Brand | E18: Retailers | F18: BE | G18: Low | H18: In Progress | I18: Bijoy Chandra Nath | J18: Fariha Jabin | K18: 6/4/2025 | L18: 9/25/2025 | M18: Provide update
A19: ▸ Contacts (1)
A20: CS-1369 | C20: CRM Contacts | Include title with the name | D20: Brand | E20: Contacts | F20: Unspec | G20: Medium | H20: Backlog | I20: Md Mashiul Azam Chowdhury Efti | J20: Constance Wolfe | K20: 5/2/2026 | L20: 5/2/2026
A21: ▸ Pipeline (5)
A22: CS-1118 | B22: Bug | C22: CRM>Pipeline>Back Button Issue | D22: Brand | E22: Pipeline | F22: Unspec | G22: High | H22: Backlog | I22: Md Mashiul Azam Chowdhury | J22: Constance Wolfe | K22: 8/19/2025 | L22: 11/10/2025 | M22: Q2
A23: CS-1348 | C23: CRM | Pipeline - Formatting Issue - Items cut off | D23: Brand | E23: Pipeline | F23: Unspec | G23: High | H23: Backlog | I23: Md Mashiul Azam Chowdhury Efti | J23: Constance Wolfe | K23: 4/21/2026 | L23: 4/21/2026
A24: CS-1349 | C24: CRM Pipeline | Enhance Editing Widget | D24: Brand | E24: Pipeline | F24: Unspec | G24: High | H24: Backlog | I24: Md Mashiul Azam Chowdhury Efti | J24: Constance Wolfe | K24: 4/21/2026 | L24: 4/21/2026
A25: CS-1150 | B25: Task | C25: CRM | Pipeline - Need Undo option in task edit | D25: Brand | E25: Pipeline | F25: Unspec | G25: Medium | H25: Backlog | I25: Md Mashiul Azam Chowdhury | J25: Constance Wolfe | K25: 8/29/2025 | L25: 9/25/2025 | M25: Q2
A26: CS-1425 | B26: Task | C26: CRM>Pipeline > Change Plan to Project > Hide/Archive Option > See Details | D26: Brand | E26: CRM Pipeline | G26: High | H26: Backlog | I26: Md Mashiul Azam Chowdhury Efti | J26: Constance Wolfe | K26: 46200.088 | L26: 46200.088
A27: CS-1059 | B27: Task | C27: crm module  delete option missing in all modules except banner | D27: Brand | E27: Pipeline | F27: Unspec | G27: Low | H27: Backlog | I27: Md Mashiul Azam Chowdhury | J27: Fariha Jabin | K27: 7/7/2025 | L27: 7/7/2025 | M27: ??
A28: ▸ Trade Spend Sandbox (37)
A29: CS-1209 | B29: Bug | C29: TSS> Add A Sku to Existing Issues | D29: Brand | E29: Trade Spend Sandbox | F29: Unspec | G29: Highest | H29: In Staging | I29: Md Mashiul Azam Chowdhury | J29: Constance Wolfe | K29: 11/1/2025 | L29: 12/22/2025 | M29: Provide Update
A30: CS-1212 | B30: Bug | C30: TSS> Add EDLP to Existing Promotion > 2nd Pop Up Box only displays 1 Product | D30: Brand | E30: Trade Spend Sandbox | F30: Unspec | G30: Highest | H30: Ready for Production | I30: Md Mashiul Azam Chowdhury | J30: Constance Wolfe | K30: 11/5/2025 | L30: 12/22/2025 | M30: Provide Update
A31: CS-1240 | B31: Task | C31: Trade Spend Calculations | D31: Brand | E31: Trade Spend Sandbox | F31: Unspec | G31: Highest | H31: Backlog | I31: Bijoy Chandra Nath | J31: Constance Wolfe | K31: 12/11/2025 | L31: 12/11/2025 | M31: Complete?
A32: CS-1254 | B32: Bug | C32: [BE] Trade Spend Sandbox - New & Discontinued Items Not Calculating according to Add & Disco. Date | D32: Brand | E32: Trade Spend Sandbox | F32: BE | G32: Highest | H32: In Staging | I32: Bijoy Chandra Nath | J32: Constance Wolfe | K32: 1/9/2026 | L32: 1/20/2026
A33: CS-725 | B33: Story | C33: Trade Spend Promotion Module | D33: Brand | E33: Trade Spend Sandbox | F33: Unspec | G33: Highest | H33: Backlog | I33: Md Mashiul Azam Chowdhury | J33: Bijoy Chandra Nath | K33: 3/12/2025 | L33: 3/12/2025 | M33: ??
A34: CS-1022 | B34: Bug | C34: Trade Spend Sandbox | Step 2 Category Issues | D34: Brand | E34: Trade Spend Sandbox | F34: Unspec | G34: High | H34: Reopened | I34: Md Mashiul Azam Chowdhury | J34: Constance Wolfe | K34: 6/21/2025 | L34: 11/10/2025
A35: CS-1090 | B35: Task | C35: Editing and Pushing from Trade spend sandbox will update corresponding Promo Planning | D35: Brand | E35: Trade Spend Sandbox | F35: Unspec | G35: High | H35: Backlog | I35: Md Mashiul Azam Chowdhury | J35: Md Mashiul Azam Chowdhury | K35: 8/6/2025 | L35: 8/6/2025 | M35: Complete?
A36: CS-1092 | B36: Sub-task | C36: [FE] Editing and Pushing from Trade spend sandbox will update corresponding Promo Planning | D36: Brand | E36: Trade Spend Sandbox | F36: FE | G36: High | H36: Backlog | I36: Md Mashiul Azam Chowdhury | J36: Md Mashiul Azam Chowdhury | K36: 8/6/2025 | L36: 8/6/2025 | M36: Fixed?
A37: CS-1095 | B37: Bug | C37: [FE] Slight Glitch after editing a promo event | D37: Brand | E37: Trade Spend Sandbox | F37: FE | G37: High | H37: Backlog | I37: Md Mashiul Azam Chowdhury | J37: Md Mashiul Azam Chowdhury | K37: 8/8/2025 | L37: 10/20/2025 | M37: Complete?
A38: CS-1174 | B38: Task | C38: Trade Spend | Sandbox and Approved Have back button from results page take user to same year | D38: Brand | E38: Trade Spend Sandbox | F38: Unspec | G38: High | H38: Backlog | I38: Md Mashiul Azam Chowdhury | J38: Constance Wolfe | K38: 9/20/2025 | L38: 9/25/2025 | M38: Complete?
A39: CS-1177 | B39: Bug | C39: The "Everyday Allowance" field does not retain entered data when navigating back from later steps. | D39: Brand | E39: Trade Spend Sandbox | F39: Unspec | G39: High | H39: Ready for Production | I39: Md Mashiul Azam Chowdhury | J39: Fariha Jabin | K39: 9/22/2025 | L39: 11/18/2025 | M39: Provide update
A40: CS-1185 | B40: Bug | C40: TSS | Create an EDLP Promotion Only Creates Error | D40: Brand | E40: Trade Spend Sandbox | F40: Unspec | G40: High | H40: Backlog | I40: Md Mashiul Azam Chowdhury | J40: Constance Wolfe | K40: 10/1/2025 | L40: 11/10/2025 | M40: Fixed?
A41: CS-1186 | B41: Bug | C41: TSS | Duplicating a Promotion Issue- Comments are not included in the copy | D41: Brand | E41: Trade Spend Sandbox | F41: Unspec | G41: High | H41: Ready for Production | I41: Bijoy Chandra Nath | J41: Constance Wolfe | K41: 10/2/2025 | L41: 11/10/2025 | M41: Provide Update
...

Sheet STORE REPORT MGMT 
A2: Concept: Many Brands have a direct to store program for smaller stores. They need a way to keep track of orders and communications.
A3: Proposed Caboodle Solution: Upload brand Store list into a separate Distributor report but very similar to the current one. Call it "House Accounts" (NOTE: I've been wanting to utilize the old UNFI & KeHE reports for agnotic reporting anyway so this may be a good solution)
A5: See Distributor Reports> Sales Details where store names, addresses and order details are provided via uplaod
A6: The void report could be converted to stores instead of warehouses so user can viscualize gaps in orders
A7: Install a email automation & Trigger API that allows users to build trigger logic for emails. For example 30-day inactivity…or lifecycle automation
A8: Need to think about email templates, I don't know that we want to get into template builders but maybe we utilize claude design? Or they could simply copy & paste a design into an editor?
A10: These 2 charts are for inspiration > It outlines how we already ingest and report very similar data
A38: SRM1

Sheet Reports
A1: Reports — 41 tickets
A3: Issue Key | B3: Type | C3: Summary | D3: Area | E3: Caboodle Module | F3: FE/BE | G3: Priority | H3: Status | I3: Assignee | J3: Reporter | K3: Created | L3: Updated | M3: Due / Note
A4: ▸ Broker Market Activities (1)
A5: CS-1203 | B5: Bug | C5: Reports>Broker Market Activity Report throws Error | D5: Reports | E5: Broker Market Activities | F5: Unspec | G5: Highest | H5: Backlog | I5: Md Mashiul Azam Chowdhury | J5: Constance Wolfe | K5: 10/28/2025 | L5: 11/10/2025 | M5: ??
A6: ▸ Category Review Report (2)
A7: CS-1149 | B7: Bug | C7: Reports | Category Review Uploads & Data Pushes | D7: Reports | E7: Category Review Report | F7: Unspec | G7: High | H7: Backlog | I7: Bijoy Chandra Nath | J7: Constance Wolfe | K7: 8/29/2025 | L7: 11/10/2025 | M7: STORY 1329
A8: CS-1291 | C8: Reports | Category Review when Reviews are uploaded in Brand Environment It's pushing to all Brands | D8: Reports | E8: Category Review Report | F8: Unspec | G8: Medium | H8: Backlog | I8: Bijoy Chandra Nath | J8: Constance Wolfe | K8: 3/31/2026 | L8: 5/4/2026 | M8: STORY 1329
A9: ▸ Retail Reports (4)
A10: CS-1204 | B10: Bug | C10: Reports > Retail Report Activities Filter Doesn't Work | D10: Reports | E10: Retail Reports | F10: Unspec | G10: Highest | H10: Backlog | I10: Md Mashiul Azam Chowdhury | J10: Constance Wolfe | K10: 10/28/2025 | L10: 11/10/2025 | M10: Q1
A11: CS-1162 | B11: Task | C11: [FE] Store Insight whole report delete by filter | D11: Reports | E11: Retail Reports | F11: FE | G11: High | H11: Reopened | I11: Md Mashiul Azam Chowdhury | J11: Md Mashiul Azam Chowdhury | K11: 9/10/2025 | L11: 11/6/2025
A12: CS-1297 | C12: New Report | Retail Portal Data Upload | D12: Reports | E12: Retail Reports | F12: Unspec | G12: High | H12: Backlog | I12: Md Mashiul Azam Chowdhury Efti | J12: Constance Wolfe | K12: 3/31/2026 | L12: 3/31/2026
A13: CS-1347 | C13: Banner List Not Sorted in Ascending Order in Retail Report > Products | D13: Reports | E13: Retail Reports | F13: Unspec | G13: Medium | H13: Backlog | I13: Bijoy Chandra Nath | J13: Taslima Akbar Keya | K13: 4/21/2026 | L13: 4/21/2026
A14: ▸ Sales Tracker (1)
A15: CS-1306 | C15: Report | Sales Tracking for Prospects | D15: Reports | E15: Sales Tracker | F15: Unspec | G15: High | H15: Backlog | I15: Md Mashiul Azam Chowdhury Efti | J15: Constance Wolfe | K15: 3/31/2026 | L15: 6/23/2026
A16: ▸ Trade Spend Rollup (5)
A17: CS-1190 | B17: Task | C17: Trade Spend Roll Up Report | Add Column for Total Trade Spend that Adds the TPR Spend w/ Ad/TPR Fees | D17: Reports | E17: Trade Spend Rollup | F17: Unspec | G17: Highest | H17: Backlog | I17: Md Mashiul Azam Chowdhury | J17: Constance Wolfe | K17: 10/11/2025 | L17: 10/11/2025 | M17: Q2
A18: CS-1339 | C18: Enhance Trade Spend Rollup Report with Hyperlinks and Spend Totals | D18: Reports | E18: Trade Spend Rollup | F18: Unspec | G18: Highest | H18: Reopened | I18: Md Mashiul Azam Chowdhury Efti | J18: Md Mashiul Azam Chowdhury Efti | K18: 4/7/2026 | L18: 5/5/2026
A19: CS-1375 | C19: [BE] Trade Spend Roll Up Report | Add Column for Total Trade Spend that Adds the TPR Spend w/ Ad/TPR Fees | D19: Reports | E19: Trade Spend Rollup | F19: BE | G19: Highest | H19: Backlog | I19: Bijoy Chandra Nath | J19: Md Mashiul Azam Chowdhury Efti | K19: 5/5/2026 | L19: 5/5/2026
A20: CS-1230 | B20: Task | C20: Reports>Trade Spend Roll Up > Updates on Headers (Net to Gross) + other Minor Changes | D20: Reports | E20: Trade Spend Rollup | F20: Unspec | G20: High | H20: Backlog | I20: Md Mashiul Azam Chowdhury | J20: Constance Wolfe | K20: 11/17/2025 | L20: 11/17/2025 | M20: Still some items to complete
A21: CS-1246 | B21: Task | C21: [BE] Add Gross Unit Calculation in Roll up report | D21: Reports | E21: Trade Spend Rollup | F21: BE | G21: High | H21: In Progress | I21: Bijoy Chandra Nath | J21: Bijoy Chandra Nath | K21: 12/24/2025 | L21: 12/24/2025 | M21: ??
A22: ▸ Monthly Report (7)
